Workbook

Sheet 요약
A1: 럭키캣 경제 설계 요약
A3: 하루 포인트 수입 (주간 평균) | B3: ='포인트 경제'!B12
A4: 시작 포인트 | B4: 300
A5: 광고 포인트 | B5: 10 × 하루 10회 = 최대 100
A6: 하루 뽑기 | B6: 일반 3 (모두 짧은 광고, 생애 첫 뽑기만 무료) + 확률업 1 (긴 광고)
A7: 1인 최대 토스 지급(원) | B7: ='보상·토스 지급'!D10
A8: 코지 Lv.5 / Lv.8 | B8: 200 / 280 코지 (활성 유저 12일 / 28일차)
A9: 고양이 카페 | B9: 1,500 포인트 + 코지 Lv.5
A10: 벚꽃 온실 | B10: 3,000 포인트 + 코지 Lv.8
A11: 가격이 매겨진 아이템 수 | B11: =COUNTA('아이템 가격'!A4:A147)
A12: 광고 eCPM | B12: '보상·토스 지급' 시트 노란 칸에 앱인토스 대시보드 값 입력
A13: 손익분기 평균 eCPM(원) | B13: ='보상·토스 지급'!B23
A14: 서버 설정 소스 | B14: economy.json · prices.json · starter.json · tutorial.json
A15: 출석 | B15: 1주차 출석 한정 아이템 7개 → 이후 주간 반복(10/10/15/15/20/20P + 7일차 상자/확률업 뽑기권 번갈아), 30·100일 기념 벽장식+배지, 리셋 없음

Sheet 포인트 경제
A1: 포인트(발바닥) 경제 — 노란 칸은 입력값
A3: 광고 1회 포인트 | B3: 10
A4: 하루 광고 시청 수 (최대 10) | B4: 8
A5: 하루 뽑기 수 (일반3+확률업1) | B5: 4
A6: 새 카드 비율 (초반 0.8 → 한 달 후 0.3) | B6: 0.6
A7: 새 카드 1장 포인트 | B7: 20
A8: 중복 1장 평균 포인트 | B8: 20
A9: 주말 2배 적용 (1=예) | B9: 0
A11: 하루 포인트 수입 (평일) | B11: =B3*B4*IF(B9=1,2,1)+B5*(B6*B7+(1-B6)*B8) | C11: ← 다른 시트의 "며칠 모으면" 계산에 사용
A12: 주간 평균 (주말 2배 반영) | B12: =(5*(B3*B4+B5*(B6*B7+(1-B6)*B8))+2*(B3*B4*2+B5*(B6*B7+(1-B6)*B8)))/7
A14: 중복 전환 | B14: 포인트
A15: 일반 (1–2★) | B15: 10
A16: 레어 (3–5★) | B16: 30
A17: 스페셜 | B17: 60
A18: 캐릭터 | B18: 60
A19: 레전드 | B19: 150
A21: 등급 (제안 확률) | B21: 일반 뽑기 | C21: 확률업 뽑기 | D21: 중복 포인트 | E21: 일반 뽑기 중복 기대값
A22: 품종 1★ | B22: 0.345 | C22: 0.15 | D22: 10 | E22: =B22*D22
A23: 품종 2★ | B23: 0.285 | C23: 0.2 | D23: 10 | E23: =B23*D23
A24: 품종 3★ | B24: 0.17 | C24: 0.22 | D24: 30 | E24: =B24*D24
A25: 품종 4★ | B25: 0.1 | C25: 0.16 | D25: 30 | E25: =B25*D25
A26: 품종 5★ | B26: 0.035 | C26: 0.1 | D26: 30 | E26: =B26*D26
A27: 스페셜 | B27: 0.04 | C27: 0.1 | D27: 60 | E27: =B27*D27
A28: 캐릭터 | B28: 0.015 | C28: 0.045 | D28: 60 | E28: =B28*D28
A29: 레전드 | B29: 0.01 | C29: 0.025 | D29: 150 | E29: =B29*D29
A30: 합계 / 중복 1장 기대 포인트 | B30: =SUM(B22:B29) | C30: =SUM(C22:C29) | E30: =SUM(E22:E29)
A31: 확률은 제안값이에요 (economy.json draws.rates_proposal). 확정 시 이 표와 서버 설정을 함께 바꿔요.
A33: 활성 유저 시뮬레이션 중앙값 (광고 8회·뽑기 4회/일, 하루 최대 3개 구매, 300명)
A34: 일차 | B34: 보유 포인트 | C34: 코지 포인트 | D34: 도감 카드 수 | E34: 누적 토스 지급(원) | F34: 보유 방 수
A35: 1 | B35: 30 | C35: 98 | D35: 4 | E35: 4 | F35: 1
A36: 2 | B36: 30 | C36: 108 | D36: 8 | E36: 8 | F36: 1
A37: 3 | B37: 40 | C37: 118 | D37: 11 | E37: 11 | F37: 1
A38: 4 | B38: 40 | C38: 128 | D38: 15 | E38: 15 | F38: 1
A39: 5 | B39: 35 | C39: 138 | D39: 18 | E39: 18 | F39: 1
A40: 6 | B40: 30 | C40: 146 | D40: 21 | E40: 21 | F40: 1
A41: 7 | B41: 40 | C41: 177 | D41: 24 | E41: 24 | F41: 1
A42: 8 | B42: 30 | C42: 183 | D42: 27 | E42: 27 | F42: 1
A43: 9 | B43: 30 | C43: 189 | D43: 30 | E43: 30 | F43: 1
A44: 10 | B44: 30 | C44: 195 | D44: 33 | E44: 33 | F44: 1
A45: 11 | B45: 40 | C45: 199 | D45: 35 | E45: 35 | F45: 1
...

Sheet 아이템 가격
A1: 하루 수입(포인트) | B1: ='포인트 경제'!B12
A3: id | B3: 이름 | C3: 방 | D3: 분류 | E3: 등급 | F3: 가격 | G3: 코지 | H3: 며칠 모으면 | I3: 플래그 | J3: 파일
A4: cattower | B4: 캣타워 | C4: moon_bedroom | D4: 가구 | E4: 큰/테마 대표 가구 | F4: 600 | G4: 25 | H4: =IF(F4=0,"기본 지급",ROUND(F4/$B$1,1)) | J4: room-assets-v6
A5: catbed | B5: 동글 쿠션 침대 | C5: moon_bedroom | D5: 가구 | E5: 일반 가구 | F5: 300 | G5: 10 | H5: =IF(F5=0,"기본 지급",ROUND(F5/$B$1,1)) | I5: starterPlaced | J5: room-assets-v6
A6: floorlamp | B6: 플로어 램프 | C6: moon_bedroom | D6: 가구 | E6: 일반 가구 | F6: 220 | G6: 10 | H6: =IF(F6=0,"기본 지급",ROUND(F6/$B$1,1)) | I6: starterPlaced | J6: room-assets-v6
A7: cabinet | B7: 발바닥 서랍장 | C7: moon_bedroom | D7: 가구 | E7: 일반 가구 | F7: 260 | G7: 10 | H7: =IF(F7=0,"기본 지급",ROUND(F7/$B$1,1)) | J7: room-assets-v6
A8: sofa | B8: 핑크 소파 | C8: moon_bedroom | D8: 가구 | E8: 큰/테마 대표 가구 | F8: 650 | G8: 25 | H8: =IF(F8=0,"기본 지급",ROUND(F8/$B$1,1)) | J8: room-assets-v6
A9: scratcher | B9: 스크래처 언덕 | C9: moon_bedroom | D9: 가구 | E9: 일반 가구 | F9: 220 | G9: 10 | H9: =IF(F9=0,"기본 지급",ROUND(F9/$B$1,1)) | J9: room-assets-v6
A10: bookshelf | B10: 민트 책장 | C10: moon_bedroom | D10: 가구 | E10: 일반 가구 | F10: 320 | G10: 10 | H10: =IF(F10=0,"기본 지급",ROUND(F10/$B$1,1)) | J10: room-assets-v6
A11: tent | B11: 냥귀 숨숨집 | C11: moon_bedroom | D11: 가구 | E11: 일반 가구 | F11: 380 | G11: 10 | H11: =IF(F11=0,"기본 지급",ROUND(F11/$B$1,1)) | J11: room-assets-v6
A12: teatable | B12: 꽃병 티 테이블 | C12: moon_bedroom | D12: 가구 | E12: 일반 가구 | F12: 240 | G12: 10 | H12: =IF(F12=0,"기본 지급",ROUND(F12/$B$1,1)) | J12: room-assets-v6
A13: desk | B13: 노트북 책상 | C13: moon_bedroom | D13: 가구 | E13: 일반 가구 | F13: 300 | G13: 10 | H13: =IF(F13=0,"기본 지급",ROUND(F13/$B$1,1)) | J13: room-assets-v6
A14: beanbag | B14: 빈백 | C14: moon_bedroom | D14: 가구 | E14: 일반 가구 | F14: 260 | G14: 10 | H14: =IF(F14=0,"기본 지급",ROUND(F14/$B$1,1)) | J14: room-assets-v6
A15: radioclock | B15: 냥이 라디오 시계 | C15: moon_bedroom | D15: 가구 | E15: 일반 가구 | F15: 280 | G15: 10 | H15: =IF(F15=0,"기본 지급",ROUND(F15/$B$1,1)) | J15: room-assets-v6
A16: bed | B16: 퀼트 침대 | C16: moon_bedroom | D16: 가구 | E16: 큰/테마 대표 가구 | F16: 700 | G16: 25 | H16: =IF(F16=0,"기본 지급",ROUND(F16/$B$1,1)) | J16: room-assets-v6
A17: fridge | B17: 민트 냉장고 | C17: moon_bedroom | D17: 가구 | E17: 일반 가구 | F17: 340 | G17: 10 | H17: =IF(F17=0,"기본 지급",ROUND(F17/$B$1,1)) | J17: room-assets-v6
A18: feeder | B18: 물고기 급식대 | C18: moon_bedroom | D18: 가구 | E18: 일반 가구 | F18: 200 | G18: 10 | H18: =IF(F18=0,"기본 지급",ROUND(F18/$B$1,1)) | J18: room-assets-v6
A19: catchair | B19: 냥귀 안락의자 | C19: moon_bedroom | D19: 가구 | E19: 일반 가구 | F19: 280 | G19: 10 | H19: =IF(F19=0,"기본 지급",ROUND(F19/$B$1,1)) | J19: room-assets-v6
A20: plant | B20: 발바닥 화분 | C20: moon_bedroom | D20: 소품 | E20: 작은 소품 | F20: 90 | G20: 4 | H20: =IF(F20=0,"기본 지급",ROUND(F20/$B$1,1)) | I20: starterPlaced | J20: room-assets-v6
A21: monstera | B21: 몬스테라 | C21: moon_bedroom | D21: 소품 | E21: 작은 소품 | F21: 130 | G21: 4 | H21: =IF(F21=0,"기본 지급",ROUND(F21/$B$1,1)) | J21: room-assets-v6
A22: fishbowl | B22: 금붕어 어항 | C22: moon_bedroom | D22: 소품 | E22: 작은 소품 | F22: 120 | G22: 4 | H22: =IF(F22=0,"기본 지급",ROUND(F22/$B$1,1)) | J22: room-assets-v6
A23: moonlamp | B23: 달 무드등 | C23: moon_bedroom | D23: 소품 | E23: 작은 소품 | F23: 140 | G23: 4 | H23: =IF(F23=0,"기본 지급",ROUND(F23/$B$1,1)) | J23: room-assets-v6
A24: yarnbasket | B24: 털실 바구니 | C24: moon_bedroom | D24: 소품 | E24: 작은 소품 | F24: 90 | G24: 4 | H24: =IF(F24=0,"기본 지급",ROUND(F24/$B$1,1)) | I24: starterDrawer | J24: room-assets-v6
A25: cushions | B25: 방석 더미 | C25: moon_bedroom | D25: 소품 | E25: 작은 소품 | F25: 100 | G25: 4 | H25: =IF(F25=0,"기본 지급",ROUND(F25/$B$1,1)) | I25: starterDrawer | J25: room-assets-v6
A26: pawrug | B26: 발바닥 러그 | C26: moon_bedroom | D26: 소품 | E26: 작은 소품 | F26: 150 | G26: 4 | H26: =IF(F26=0,"기본 지급",ROUND(F26/$B$1,1)) | I26: starterPlaced | J26: room-assets-v6
A27: xmastree | B27: 미니 트리 | C27: moon_bedroom | D27: 소품 | E27: 작은 소품 | F27: 150 | G27: 4 | H27: =IF(F27=0,"기본 지급",ROUND(F27/$B$1,1)) | I27: limited | J27: room-assets-v6
A28: maneki | B28: 마네키네코 | C28: moon_bedroom | D28: 소품 | E28: 작은 소품 | F28: 150 | G28: 4 | H28: =IF(F28=0,"기본 지급",ROUND(F28/$B$1,1)) | J28: room-assets-v6
A29: gramophone | B29: 축음기 | C29: moon_bedroom | D29: 소품 | E29: 작은 소품 | F29: 140 | G29: 4 | H29: =IF(F29=0,"기본 지급",ROUND(F29/$B$1,1)) | J29: room-assets-v6
A30: globe | B30: 지구본 | C30: moon_bedroom | D30: 소품 | E30: 작은 소품 | F30: 120 | G30: 4 | H30: =IF(F30=0,"기본 지급",ROUND(F30/$B$1,1)) | J30: room-assets-v6
A31: catcactus | B31: 냥이 선인장 | C31: moon_bedroom | D31: 소품 | E31: 작은 소품 | F31: 80 | G31: 4 | H31: =IF(F31=0,"기본 지급",ROUND(F31/$B$1,1)) | J31: room-assets-v6
A32: archmirror | B32: 아치 거울 | C32: moon_bedroom | D32: 소품 | E32: 작은 소품 | F32: 150 | G32: 4 | H32: =IF(F32=0,"기본 지급",ROUND(F32/$B$1,1)) | J32: room-assets-v6
A33: aquarium | B33: 수족관 장 | C33: moon_bedroom | D33: 소품 | E33: 작은 소품 | F33: 150 | G33: 4 | H33: =IF(F33=0,"기본 지급",ROUND(F33/$B$1,1)) | J33: room-assets-v6
A34: starlight | B34: 별 수면등 | C34: moon_bedroom | D34: 소품 | E34: 작은 소품 | F34: 110 | G34: 4 | H34: =IF(F34=0,"기본 지급",ROUND(F34/$B$1,1)) | J34: room-assets-v6
A35: gifts | B35: 선물 상자 | C35: moon_bedroom | D35: 소품 | E35: 작은 소품 | F35: 100 | G35: 4 | H35: =IF(F35=0,"기본 지급",ROUND(F35/$B$1,1)) | I35: limited | J35: room-assets-v6
A36: archwindow | B36: 커튼 창문 | C36: moon_bedroom | D36: 벽 꾸미기 | E36: 벽 꾸미기 | F36: 200 | G36: 6 | H36: =IF(F36=0,"기본 지급",ROUND(F36/$B$1,1)) | I36: starterPlaced | J36: room-assets-v6
A37: porthole | B37: 동그란 창 | C37: moon_bedroom | D37: 벽 꾸미기 | E37: 벽 꾸미기 | F37: 180 | G37: 6 | H37: =IF(F37=0,"기본 지급",ROUND(F37/$B$1,1)) | J37: room-assets-v6
A38: squareframe | B38: 네모 액자 | C38: moon_bedroom | D38: 카드액자 | E38: 벽 꾸미기 | F38: 120 | G38: 6 | H38: =IF(F38=0,"기본 지급",ROUND(F38/$B$1,1)) | J38: room-assets-v6
A39: cardframe | B39: 리본 카드 액자 | C39: moon_bedroom | D39: 카드액자 | E39: 벽 꾸미기 | F39: 100 | G39: 6 | H39: =IF(F39=0,"기본 지급",ROUND(F39/$B$1,1)) | I39: starterPlaced | J39: room-assets-v6
A40: catclock | B40: 냥이 벽시계 | C40: moon_bedroom | D40: 벽 꾸미기 | E40: 벽 꾸미기 | F40: 160 | G40: 6 | H40: =IF(F40=0,"기본 지급",ROUND(F40/$B$1,1)) | J40: room-assets-v6
A41: fairylights | B41: 꼬마전구 | C41: moon_bedroom | D41: 벽 꾸미기 | E41: 벽 꾸미기 | F41: 180 | G41: 6 | H41: =IF(F41=0,"기본 지급",ROUND(F41/$B$1,1)) | J41: room-assets-v6
...

Sheet 방
A1: 하루 수입(포인트) | B1: ='포인트 경제'!B12
A3: 방 | B3: 해금 포인트 | C3: 필요 코지 Lv | D3: 필요 코지 포인트 | E3: 며칠 모으면(포인트만) | F3: 해금 시 지급
A4: 달밤 침실 | B4: 0 | C4: - | D4: =IFERROR(VLOOKUP(C4,$A$13:$B$22,2,FALSE()),"-") | E4: =IF(B4=0,"기본",ROUND(B4/$B$1,1)) | F4: -
A5: 고양이 카페 | B5: 1500 | C5: 5 | D5: =IFERROR(VLOOKUP(C5,$A$13:$B$22,2,FALSE()),"-") | E5: =IF(B5=0,"기본",ROUND(B5/$B$1,1)) | F5: cafe_table, heart_chair, chalk_stand, menu_board
A6: 벚꽃 온실 정원 | B6: 3000 | C6: 8 | D6: =IFERROR(VLOOKUP(C6,$A$13:$B$22,2,FALSE()),"-") | E6: =IF(B6=0,"기본",ROUND(B6/$B$1,1)) | F6: tea_table_white, tulip_planter, watering_can, hanging_basket
A7: _future | B7: 5000 | C7: 10 | D7: =IFERROR(VLOOKUP(C7,$A$13:$B$22,2,FALSE()),"-") | E7: =IF(B7=0,"기본",ROUND(B7/$B$1,1)) | F7: 3–4개
A12: 코지 Lv | B12: 최소 코지 포인트 | C12: 목표
A13: 1 | B13: 0
A14: 2 | B14: 100
A15: 3 | B15: 130
A16: 4 | B16: 165
A17: 5 | B17: 200 | C17: 활성 유저 10–14일차 (시뮬 12일)
A18: 6 | B18: 225
A19: 7 | B19: 250
A20: 8 | B20: 280 | C20: 25–30일차 (시뮬 28일)
A21: 9 | B21: 330
A22: 10 | B22: 400
A24: 코지 포인트 = 보유 아이템의 등급별 코지 합 (작은 소품 4 · 일반 가구 10 · 큰/대표 25 · 벽 꾸미기 6 · 벽지/바닥 8 · 레전드 60)
A25: 시뮬레이션에서 고양이 카페 해금(포인트 1,500 모으기 포함) 중앙값은 21일차예요.

Sheet 보상·토스 지급
A1: 토스 지급 (1인 최대)
A3: 보상 | B3: 횟수 | C3: 토스(원) | D3: 토스 합계 | E3: 포인트 | F3: 포인트 합계
A4: 새 카드 첫 획득 | B4: 107 | C4: 1 | D4: =B4*C4 | E4: 20 | F4: =B4*E4
A5: 품종 1–5★ 완성 | B5: 18 | C5: 10 | D5: =B5*C5 | E5: 200 | F5: =B5*E5
A6: 스페셜 세트 완성 | B6: 1 | C6: 10 | D6: =B6*C6 | E6: 300 | F6: =B6*E6
A7: 캐릭터 세트 완성 | B7: 1 | C7: 10 | D7: =B7*C7 | E7: 300 | F7: =B7*E7
A8: 레전드 세트 완성 | B8: 1 | C8: 10 | D8: =B8*C8 | E8: 300 | F8: =B8*E8
A9: 도감 전체 완성 | B9: 1 | C9: 100 | D9: =B9*C9 | E9: 3000 | F9: =B9*E9
A10: 합계 | D10: =SUM(D4:D9) | F10: =SUM(F4:F9)
A11: 검증 (417원이어야 해요) | D11: =IF(D10=417,"OK","확인 필요")
A13: 광고 수익 손익분기
A14: 짧은 광고 eCPM (원) | C14: 앱인토스 대시보드에서 입력
A15: 긴 광고 eCPM (원) | C15: 앱인토스 대시보드에서 입력
A16: 기간(일) | B16: 30
A17: 1인 하루 짧은 광고 수 (뽑기 3 + 포인트 8) | B17: 11
A18: 1인 하루 긴 광고 수 | B18: 1
A19: 기간 내 1인 토스 지급(원, 시뮬 30일 중앙값) | B19: 83
A21: 기간 내 1인 광고 수익(원) | B21: =IF(OR(B14="",B15=""),"eCPM 입력 필요",B16*(B17*B14+B18*B15)/1000)
A22: 1인 순이익(원) = 광고 수익 − 토스 지급 | B22: =IF(ISNUMBER(B21),B21-B19,"eCPM 입력 필요")
A23: 손익분기 평균 eCPM (원, 모든 광고 동일 가정) | B23: =B19/(B16*(B17+B18)/1000)
A24: 손익분기 짧은 광고 eCPM (긴 광고 eCPM 입력 시) | B24: =IF(B15="","긴 광고 eCPM 입력 필요",(B19*1000/B16-B18*B15)/B17)
A25: 최대 지급 417원 회수에 필요한 광고 수 (평균 eCPM 입력 시) | B25: =IF(B14="","eCPM 입력 필요",417*1000/B14)

Sheet 신규 지급
A1: 시작 포인트: 300
A3: 구분 | B3: id | C3: 이름 | D3: 등급 | E3: 코지 | F3: 가격 환산
A4: 첫 방 배치 (히어로 고양이 포함) | B4: catbed | C4: 동글 쿠션 침대 | D4: 일반 가구 | E4: 10 | F4: 300
A5: 첫 방 배치 | B5: floorlamp | C5: 플로어 램프 | D5: 일반 가구 | E5: 10 | F5: 220
A6: 첫 방 배치 | B6: plant | C6: 발바닥 화분 | D6: 작은 소품 | E6: 4 | F6: 90
A7: 첫 방 배치 | B7: pawrug | C7: 발바닥 러그 | D7: 작은 소품 | E7: 4 | F7: 150
A8: 첫 방 배치 | B8: archwindow | C8: 커튼 창문 | D8: 벽 꾸미기 | E8: 6 | F8: 200
A9: 첫 방 배치 | B9: cardframe | C9: 리본 카드 액자 | D9: 벽 꾸미기 | E9: 6 | F9: 100
A10: 첫 방 기본 바닥 | B10: floor_wood_honey | C10: 꿀빛 원목 | D10: 벽지/바닥 | E10: 8 | F10: 0
A11: 첫 방 기본 벽지 | B11: wall_plum_sparkle | C11: 플럼 반짝이 | D11: 벽지/바닥 | E11: 8 | F11: 0
A12: 서랍 | B12: floor_check_pink | C12: 핑크 체크 | D12: 벽지/바닥 | E12: 8 | F12: 240
A13: 서랍 | B13: wall_mint_gingham | C13: 민트 깅엄 | D13: 벽지/바닥 | E13: 8 | F13: 240
A14: 서랍 | B14: cushions | C14: 방석 더미 | D14: 작은 소품 | E14: 4 | F14: 100
A15: 서랍 | B15: yarnbasket | C15: 털실 바구니 | D15: 작은 소품 | E15: 4 | F15: 90 | G15: 메모
A16: 출석 1일차 (출석 한정) | B16: att_moon_cactus | C16: 달빛 냥이 선인장 | D16: 작은 소품 | E16: 4 | F16: 80 | G16: 출석 아이템은 가격 없음(구매 불가) → 가격 환산 합계에서 제외
A17: 출석 2일차 (출석 한정) | B17: att_stamp_calendar | C17: 출석 도장 달력 | D17: 벽 꾸미기 | E17: 6 | F17: 100
A18: 출석 3일차 (출석 한정) | B18: att_pink_starlight | C18: 핑크 별 수면등 | D18: 작은 소품 | E18: 4 | F18: 110
A19: 출석 4일차 (출석 한정) | B19: att_night_bunting | C19: 밤하늘 가랜드 | D19: 벽 꾸미기 | E19: 6 | F19: 130
A20: 출석 5일차 (출석 한정) | B20: att_moon_globe | C20: 달빛 지구본 | D20: 작은 소품 | E20: 4 | F20: 120
A21: 출석 6일차 (출석 한정) | B21: att_sakura_fishbowl | C21: 벚꽃 금붕어 어항 | D21: 작은 소품 | E21: 4 | F21: 120
A22: 출석 7일차 (출석 한정) | B22: att_moon_cattower | C22: 달밤 캣타워 | D22: 큰/테마 대표 가구 | E22: 25 | F22: 600
A23: 합계 | E23: =SUM(E4:E22) | F23: =SUM(F4:F22)

Sheet 출석
A1: 출석 보상 (starter.json → attendance) — 노란 칸은 입력값
A3: 규칙 | B3: 누적 출석일 기준 · 빠져도 리셋 없음 · 하루 1회(KST 00:00)
A5: 1주차 (처음 한 번) | B5: id | C5: 이름 | D5: 등급 | E5: 코지 | F5: 구매
A6: 1일차 | B6: att_moon_cactus | C6: 달빛 냥이 선인장 | D6: 작은 소품 | E6: 4 | F6: 불가 · 출석 한정
A7: 2일차 | B7: att_stamp_calendar | C7: 출석 도장 달력 | D7: 벽 꾸미기 | E7: 6 | F7: 불가 · 출석 한정
A8: 3일차 | B8: att_pink_starlight | C8: 핑크 별 수면등 | D8: 작은 소품 | E8: 4 | F8: 불가 · 출석 한정
A9: 4일차 | B9: att_night_bunting | C9: 밤하늘 가랜드 | D9: 벽 꾸미기 | E9: 6 | F9: 불가 · 출석 한정
A10: 5일차 | B10: att_moon_globe | C10: 달빛 지구본 | D10: 작은 소품 | E10: 4 | F10: 불가 · 출석 한정
A11: 6일차 | B11: att_sakura_fishbowl | C11: 벚꽃 금붕어 어항 | D11: 작은 소품 | E11: 4 | F11: 불가 · 출석 한정
A12: 7일차 | B12: att_moon_cattower | C12: 달밤 캣타워 | D12: 큰/테마 대표 가구 | E12: 25 | F12: 불가 · 출석 한정
A14: 주간 반복 (8일차~) | B14: 포인트 | C14: 비고
A15: 1일차 | B15: 10
A16: 2일차 | B16: 10
A17: 3일차 | B17: 15
A18: 4일차 | B18: 15
A19: 5일차 | B19: 20
A20: 6일차 | B20: 20
A21: 7일차 | C21: 홀수 주기: 출석 선물 상자 / 짝수 주기: 확률업 뽑기권 1장 (mode)
A22: 주간 포인트 합계 | B22: =SUM(B15:B20)
A24: 출석 선물 상자 풀 | B24: id | C24: 이름 | D24: 등급 | E24: 코지 | F24: 구매
A25: 상자 | B25: att_lav_moonlamp | C25: 라벤더 달 무드등 | D25: 작은 소품 | E25: 4 | F25: 불가 · 출석 한정
A26: 상자 | B26: att_rose_gramophone | C26: 로즈 축음기 | D26: 작은 소품 | E26: 4 | F26: 불가 · 출석 한정
A27: 상자 | B27: att_mint_yarnbasket | C27: 민트 털실 바구니 | D27: 작은 소품 | E27: 4 | F27: 불가 · 출석 한정
A28: 상자 | B28: att_lav_cushions | C28: 파스텔 방석 더미 | D28: 작은 소품 | E28: 4 | F28: 불가 · 출석 한정
A29: 상자 | B29: att_sky_catclock | C29: 하늘빛 냥이 벽시계 | D29: 벽 꾸미기 | E29: 6 | F29: 불가 · 출석 한정
A30: 다 모은 뒤 | C30: 100 포인트로 대체
A32: 누적 기념 | B32: id | C32: 이름 | D32: 등급 | E32: 배지 | F32: 구매
A33: 30일 | B33: att_m30_goldneon | C33: 30일 골드 하트 네온 | D33: 벽 꾸미기 | E33: badge_att_30 | F33: 불가 · 출석 한정
A34: 100일 | B34: att_m100_nightlamp | C34: 100일 별밤 벽등 | D34: 벽 꾸미기 | E34: badge_att_100 | F34: 불가 · 출석 한정
A36: 30일 동안 받는 포인트(1주차 후 23일) | B36: =B22*3+B15+B16
A37: 참고 | B37: 광고 포인트 하루 최대 100 대비 출석은 주 90 + 7일차 보너스

Sheet 튜토리얼
A1: 단계 | B1: 화면 | C1: 대상 요소 | D1: 문구 | E1: 토스트/보조 | F1: 동작
A2: 1 | B2: main | C2: #stage-cat | D2: 톡, 깨워 볼까요? | E2: 첫 뽑기는 광고 없이 무료예요 | F2: tap
A3: 2 | B3: draw-reveal | C3: #reveal-card | D3: 오늘의 행운 문구가 도착했어요 | E3: 도감에 등록됐어요! 토스 1원 받았어요 | F3: tap #btn-to-dex (도감에 넣기)
A4: 3 | B4: main→dex | C4: #icon-dex | D4: 도감에서 모은 카드를 볼 수 있어요 | E4: 방금 뽑은 카드가 여기 들어갔어요 | F4: tap
A5: 4 | B5: room | C5: #drawer-item-0 | D5: 서랍에서 아이템을 꺼내 방에 놓아 보세요 | E5: 다 꾸몄으면 완료를 눌러요 | F5: drag + tap 완료
A7: 건너뛰기: 모든 단계 우상단 "건너뛰기", 보상은 그대로 지급. 1분 이내.
A9: 일차 | B9: id | C9: 대상 요소 | D9: 새 기능 말풍선 문구
A10: 2 | B10: intro-extra-draws | C10: #chip-draws | D10: 광고를 보면 하루 2번 더 뽑을 수 있어요
A11: 3 | B11: intro-rateup | C11: #btn-rateup | D11: 확률업 뽑기가 열렸어요! 레어 이상이 더 잘 나와요
A12: 4 | B12: intro-paw-ads | C12: #btn-paw-ad | D12: 광고 보고 포인트 10개 받아요 (하루 10번까지)
A13: 5 | B13: intro-dup-convert | C13: #dex-dup-convert | D13: 겹친 카드는 포인트로 바꿀 수 있어요
A14: 6 | B14: intro-cozy | C14: #cozy-meter | D14: 아이템을 모을수록 아늑함 레벨이 올라가요

Sheet 운영 지표
A1: 지표 | B1: 정의 | C1: 계산 | D1: 목표 (입력) | E1: 데이터
A2: D1 리텐션 | B2: 설치 다음 날 재방문 비율 | C2: D1 방문자 / 설치자 | E2: 앱인토스 대시보드
A3: D7 리텐션 | B3: 7일차 재방문 비율 | C3: D7 방문자 / 설치자 | E3: 앱인토스 대시보드
A4: 광고 시청 / DAU | B4: 하루 1인당 광고 완료 수 | C4: 광고 완료 콜백 수 / DAU | E4: 서버 로그 (ad_complete)
A5: 광고 수익 / 유저 | B5: 1인당 일 광고 수익 | C5: 광고 수익 / DAU | E5: 앱인토스 대시보드
A6: 토스 지급 / 유저 | B6: 1인당 누적 토스 지급 | C6: 토스 지급 합 / 누적 유저 | E6: 서버 reward_ledger
A7: 도감 완성률 | B7: 유저별 보유 카드 / 107 분포 | C7: 보유 카드 수 중앙값 / 107 | E7: 서버 dex
A8: 뽑기 슬롯 사용률 | B8: 하루 4회 중 사용 | C8: 사용 뽑기 / (DAU×4) | E8: 서버 draws
A9: 포인트 수지 | B9: 발행 vs 소비 | C9: 발행 포인트 − 소비 포인트 (일별) | E9: 서버 paw_ledger
A10: 방 해금률 | B10: 카페/온실 해금 유저 비율 | C10: 해금 유저 / 활성 유저 | E10: 서버 rooms
A11: 튜토리얼 완료율 | B11: 4단계 완료 or 건너뛰기 | C11: 완료 / 시작 | E11: 클라이언트 이벤트
A13: 운영 이벤트
A14: 월간 카드팩: 새 카드 추가 시 economy.json tossPayout·도감 수 재계산
A15: 시즌 방: 해금 5,000 포인트+, 기간 한정 노출
A16: 한정 아이템: 크리스마스 트리·선물 상자 (겨울 시즌)
A17: 주말 포인트 2배: 광고 포인트만, events.weekendDoublePaw
A18: 친구 초대: 서로 100 포인트 (제안값, 기본 꺼짐)
A19: 어뷰징 방지: 토스 1원은 토스 계정당 1회 서버 검증, 광고 보상은 광고 완료 콜백 후에만
